<?xml version="1.0" ?>
<testsuite errors="2" failures="0" name="Test-20190804185755" tests="3" time="0.004">
	<testcase classname="Test" name="test_nombre_casos_prueba" time="0.001"/>
	<testcase classname="Test" name="test_descuento_2" time="0.002">
		<error message="11.1 != 0" type="AssertionError">
<![CDATA[Traceback (most recent call last):
  File "test.py", line 24, in test_descuento_2
    self.assertEqual(resultado, 0)
AssertionError: 11.1 != 0
]]>		</error>
	</testcase>
	<testcase classname="Test" name="test_descuento_no_valido" time="0.001">
		<error message="0 != 11.1" type="AssertionError">
<![CDATA[Traceback (most recent call last):
  File "test.py", line 18, in test_descuento_no_valido
    self.assertEqual(resultado, 11.1)
AssertionError: 0 != 11.1
]]>		</error>
	</testcase>
	<system-out>
<![CDATA[]]>	</system-out>
	<system-err>
<![CDATA[]]>	</system-err>
</testsuite>
