<?xml version="1.0" ?>
<testsuite errors="1" failures="0" name="Test-20190805011933" tests="12" time="0.007">
	<testcase classname="Test" name="test_calcular_descuento_cliente_jovenes" time="0.001"/>
	<testcase classname="Test" name="test_calcular_descuento_clientes_generales" time="0.000"/>
	<testcase classname="Test" name="test_calcular_descuento_clientes_generales_valor_mayor_a_500" time="0.000"/>
	<testcase classname="Test" name="test_calcular_descuento_familias" time="0.001"/>
	<testcase classname="Test" name="test_calcular_descuento_familias_grandes" time="0.000"/>
	<testcase classname="Test" name="test_calcular_descuento_mayores_edad" time="0.000"/>
	<testcase classname="Test" name="test_calcular_descuento_mayores_edad_grandes_valores" time="0.001"/>
	<testcase classname="Test" name="test_calcular_descuento_no_valido" time="0.000"/>
	<testcase classname="Test" name="test_calcular_descuentos_especiales" time="0.000"/>
	<testcase classname="Test" name="test_calcular_descuentos_especiales_valores_altos" time="0.001"/>
	<testcase classname="Test" name="test_nombre_casos_prueba" time="0.000"/>
	<testcase classname="Test" name="test_calcular_descuentos_especiales_2_dependientes" time="0.003">
		<error message="875.3499999999999 != 1750.35" type="AssertionError">
<![CDATA[Traceback (most recent call last):
  File "test.py", line 38, in test_calcular_descuentos_especiales_2_dependientes
    self.assertEqual(descuento, 1750.35)
AssertionError: 875.3499999999999 != 1750.35
]]>		</error>
	</testcase>
	<system-out>
<![CDATA[]]>	</system-out>
	<system-err>
<![CDATA[]]>	</system-err>
</testsuite>
