<?xml version="1.0" ?>
<testsuite errors="1" failures="0" name="Test-20190804180830" tests="6" time="0.004">
	<testcase classname="Test" name="test_descuento_no_valido" time="0.001"/>
	<testcase classname="Test" name="test_descuento_para_mayores" time="0.001"/>
	<testcase classname="Test" name="test_descuento_para_mayores2" time="0.000"/>
	<testcase classname="Test" name="test_descuento_para_mayores4" time="0.001"/>
	<testcase classname="Test" name="test_nombre_casos_prueba" time="0.000"/>
	<testcase classname="Test" name="test_descuento_para_mayores3" time="0.002">
		<error message="7.01 != 0" type="AssertionError">
<![CDATA[Traceback (most recent call last):
  File "test.py", line 29, in test_descuento_para_mayores3
    self.assertEqual(resultado, 0)
AssertionError: 7.01 != 0
]]>		</error>
	</testcase>
	<system-out>
<![CDATA[op5
op1
op2
op4
op2
]]>	</system-out>
	<system-err>
<![CDATA[]]>	</system-err>
</testsuite>
