<?xml version="1.0" ?>
<testsuite errors="1" failures="0" name="Test-20190805005445" tests="9" time="0.010">
	<testcase classname="Test" name="test_calcular_descuento_cliente_jovenes" time="0.001"/>
	<testcase classname="Test" name="test_calcular_descuento_clientes_generales" time="0.001"/>
	<testcase classname="Test" name="test_calcular_descuento_familias_grandes" time="0.001"/>
	<testcase classname="Test" name="test_calcular_descuento_mayores_edad" time="0.001"/>
	<testcase classname="Test" name="test_calcular_descuento_mayores_edad_grandes_valores" time="0.000"/>
	<testcase classname="Test" name="test_calcular_descuento_no_valido" time="0.000"/>
	<testcase classname="Test" name="test_calcular_descuentos_especiales" time="0.001"/>
	<testcase classname="Test" name="test_nombre_casos_prueba" time="0.001"/>
	<testcase classname="Test" name="test_calcular_descuento_familias" time="0.004">
		<error message="50.1 != 200.4" type="AssertionError">
<![CDATA[Traceback (most recent call last):
  File "test.py", line 24, in test_calcular_descuento_familias
    self.assertEqual(descuento, 200.4)
AssertionError: 50.1 != 200.4
]]>		</error>
	</testcase>
	<system-out>
<![CDATA[]]>	</system-out>
	<system-err>
<![CDATA[]]>	</system-err>
</testsuite>
