<?xml version="1.0" ?>
<testsuite errors="1" failures="0" name="TestDescuentos-20190826093504" tests="11" time="0.002">
	<testcase classname="TestDescuentos" name="test_descuento_clientes_1" time="0.000"/>
	<testcase classname="TestDescuentos" name="test_descuento_familias" time="0.000"/>
	<testcase classname="TestDescuentos" name="test_descuento_familias_mayor_6" time="0.000"/>
	<testcase classname="TestDescuentos" name="test_descuento_familias_no_aplica" time="0.000"/>
	<testcase classname="TestDescuentos" name="test_descuentos_clientes" time="0.000"/>
	<testcase classname="TestDescuentos" name="test_descuentos_especiales" time="0.000"/>
	<testcase classname="TestDescuentos" name="test_descuentos_mayores_edad" time="0.000"/>
	<testcase classname="TestDescuentos" name="test_descuentos_mayores_edad_2" time="0.000"/>
	<testcase classname="TestDescuentos" name="test_menor_edad" time="0.000"/>
	<testcase classname="TestDescuentos" name="test_nombre_casos_prueba" time="0.000"/>
	<testcase classname="TestDescuentos" name="test_descuentos_clientes_2" time="0.002">
		<error message="100 != 160.0" type="AssertionError">
<![CDATA[Traceback (most recent call last):
  File "test.py", line 77, in test_descuentos_clientes_2
    self.assertEqual(100, descuento)
AssertionError: 100 != 160.0
]]>		</error>
	</testcase>
	<system-out>
<![CDATA[]]>	</system-out>
	<system-err>
<![CDATA[]]>	</system-err>
</testsuite>
