<?xml version="1.0" ?>
<testsuite errors="1" failures="0" name="Test-20190805003858" tests="7" time="0.008">
	<testcase classname="Test" name="test_calcular_descuento_cliente_jovenes" time="0.001"/>
	<testcase classname="Test" name="test_calcular_descuento_clientes_generales" time="0.001"/>
	<testcase classname="Test" name="test_calcular_descuento_familias" time="0.000"/>
	<testcase classname="Test" name="test_calcular_descuento_mayores_edad" time="0.001"/>
	<testcase classname="Test" name="test_calcular_descuento_no_valido" time="0.001"/>
	<testcase classname="Test" name="test_nombre_casos_prueba" time="0.001"/>
	<testcase classname="Test" name="test_calcular_descuento_familias_grandes" time="0.003">
		<error message="100.2 != 601.2" type="AssertionError">
<![CDATA[Traceback (most recent call last):
  File "test.py", line 29, in test_calcular_descuento_familias_grandes
    self.assertEqual(descuento, 601.2)
AssertionError: 100.2 != 601.2
]]>		</error>
	</testcase>
	<system-out>
<![CDATA[]]>	</system-out>
	<system-err>
<![CDATA[]]>	</system-err>
</testsuite>
