<?xml version="1.0" ?>
<testsuite errors="1" failures="0" name="Test-20190804190111" tests="3" time="0.003">
	<testcase classname="Test" name="test_descuento_no_valido" time="0.001"/>
	<testcase classname="Test" name="test_nombre_casos_prueba" time="0.000"/>
	<testcase classname="Test" name="test_descuento_2" time="0.002">
		<error message="5.1000000000000005 != 11.1" type="AssertionError">
<![CDATA[Traceback (most recent call last):
  File "test.py", line 24, in test_descuento_2
    self.assertEqual(resultado, 11.1)
AssertionError: 5.1000000000000005 != 11.1
]]>		</error>
	</testcase>
	<system-out>
<![CDATA[]]>	</system-out>
	<system-err>
<![CDATA[]]>	</system-err>
</testsuite>
