<?xml version="1.0" ?>
<testsuite errors="3" failures="0" name="Test-20190804181005" tests="6" time="0.011">
	<testcase classname="Test" name="test_descuento_no_valido" time="0.003"/>
	<testcase classname="Test" name="test_descuento_para_mayores" time="0.001"/>
	<testcase classname="Test" name="test_nombre_casos_prueba" time="0.000"/>
	<testcase classname="Test" name="test_descuento_para_mayores2" time="0.003">
		<error message="250.5 != 50.1" type="AssertionError">
<![CDATA[Traceback (most recent call last):
  File "test.py", line 28, in test_descuento_para_mayores2
    self.assertEqual(resultado, 50.1)
AssertionError: 250.5 != 50.1
]]>		</error>
	</testcase>
	<testcase classname="Test" name="test_descuento_para_mayores3" time="0.002">
		<error message="7.01 != 0" type="AssertionError">
<![CDATA[Traceback (most recent call last):
  File "test.py", line 33, in test_descuento_para_mayores3
    self.assertEqual(resultado, 0)
AssertionError: 7.01 != 0
]]>		</error>
	</testcase>
	<testcase classname="Test" name="test_descuento_para_mayores4" time="0.002">
		<error message="175.5 != 70.2" type="AssertionError">
<![CDATA[Traceback (most recent call last):
  File "test.py", line 38, in test_descuento_para_mayores4
    self.assertEqual(resultado, 70.2)
AssertionError: 175.5 != 70.2
]]>		</error>
	</testcase>
	<system-out>
<![CDATA[op5
op1
op3
op4
op3
]]>	</system-out>
	<system-err>
<![CDATA[]]>	</system-err>
</testsuite>
