<?xml version="1.0" ?>
<testsuite errors="1" failures="0" name="Test-20190804180042" tests="6" time="0.004">
	<testcase classname="Test" name="test_descuento_no_valido" time="0.000"/>
	<testcase classname="Test" name="test_descuento_para_mayores" time="0.000"/>
	<testcase classname="Test" name="test_descuento_para_mayores2" time="0.000"/>
	<testcase classname="Test" name="test_descuento_para_mayores3" time="0.000"/>
	<testcase classname="Test" name="test_nombre_casos_prueba" time="0.001"/>
	<testcase classname="Test" name="test_descuento_para_mayores4" time="0.003">
		<error message="70.2 != 50.1" type="AssertionError">
<![CDATA[Traceback (most recent call last):
  File "test.py", line 33, in test_descuento_para_mayores4
    self.assertEqual(resultado, 50.1)
AssertionError: 70.2 != 50.1
]]>		</error>
	</testcase>
	<system-out>
<![CDATA[]]>	</system-out>
	<system-err>
<![CDATA[]]>	</system-err>
</testsuite>
